[2024-05-01T17:36:33.989+0300] {local_task_job_runner.py:120} INFO - ::group::Pre task execution logs
[2024-05-01T17:36:34.144+0300] {taskinstance.py:2073} INFO - Dependencies all met for dep_context=non-requeueable deps ti=<TaskInstance: dbt_dag.dbt_debug manual__2024-05-01T13:04:12.949516+00:00 [queued]>
[2024-05-01T17:36:34.164+0300] {taskinstance.py:2073} INFO - Dependencies all met for dep_context=requeueable deps ti=<TaskInstance: dbt_dag.dbt_debug manual__2024-05-01T13:04:12.949516+00:00 [queued]>
[2024-05-01T17:36:34.165+0300] {taskinstance.py:2303} INFO - Starting attempt 3 of 4
[2024-05-01T17:36:40.750+0300] {taskinstance.py:2327} INFO - Executing <Task(BashOperator): dbt_debug> on 2024-05-01 13:04:12.949516+00:00
[2024-05-01T17:36:40.764+0300] {standard_task_runner.py:63} INFO - Started process 7951 to run task
[2024-05-01T17:36:40.773+0300] {standard_task_runner.py:90} INFO - Running: ['airflow', 'tasks', 'run', 'dbt_dag', 'dbt_debug', 'manual__2024-05-01T13:04:12.949516+00:00', '--job-id', '38', '--raw', '--subdir', 'DAGS_FOLDER/bash.py', '--cfg-path', '/tmp/tmpwrvbhn_4']
[2024-05-01T17:36:40.776+0300] {standard_task_runner.py:91} INFO - Job 38: Subtask dbt_debug
[2024-05-01T17:36:41.716+0300] {task_command.py:426} INFO - Running <TaskInstance: dbt_dag.dbt_debug manual__2024-05-01T13:04:12.949516+00:00 [running]> on host yohanes-Satellite-Pro-C50-A363
[2024-05-01T17:36:42.216+0300] {taskinstance.py:2644} INFO - Exporting env vars: AIRFLOW_CTX_DAG_OWNER='airflow' AIRFLOW_CTX_DAG_ID='dbt_dag' AIRFLOW_CTX_TASK_ID='dbt_debug' AIRFLOW_CTX_EXECUTION_DATE='2024-05-01T13:04:12.949516+00:00' AIRFLOW_CTX_TRY_NUMBER='3' AIRFLOW_CTX_DAG_RUN_ID='manual__2024-05-01T13:04:12.949516+00:00'
[2024-05-01T17:36:42.217+0300] {taskinstance.py:430} INFO - ::endgroup::
[2024-05-01T17:36:44.090+0300] {subprocess.py:63} INFO - Tmp dir root location: /tmp
[2024-05-01T17:36:44.091+0300] {subprocess.py:75} INFO - Running command: ['/usr/bin/bash', '-c', 'dbt debug']
[2024-05-01T17:36:44.107+0300] {subprocess.py:86} INFO - Output:
[2024-05-01T17:40:22.943+0300] {subprocess.py:93} INFO - [0m14:40:22  Running with dbt=1.7.13
[2024-05-01T17:40:23.336+0300] {subprocess.py:93} INFO - [0m14:40:22  dbt version: 1.7.13
[2024-05-01T17:40:23.337+0300] {subprocess.py:93} INFO - [0m14:40:22  python version: 3.8.10
[2024-05-01T17:40:23.337+0300] {subprocess.py:93} INFO - [0m14:40:22  python path: /home/yohanes/Documents/10academy/week2_2/10ac_city_traffic_data_warehouse_week2/week2_env/bin/python3
[2024-05-01T17:40:23.338+0300] {subprocess.py:93} INFO - [0m14:40:22  os info: Linux-5.15.0-105-generic-x86_64-with-glibc2.29
[2024-05-01T17:40:26.909+0300] {subprocess.py:93} INFO - [0m14:40:26  Using profiles dir at /home/yohanes/.dbt
[2024-05-01T17:40:26.922+0300] {subprocess.py:93} INFO - [0m14:40:26  Using profiles.yml file at /home/yohanes/.dbt/profiles.yml
[2024-05-01T17:40:26.925+0300] {subprocess.py:93} INFO - [0m14:40:26  Using dbt_project.yml file at /tmp/airflowtmpxwlh0su8/dbt_project.yml
[2024-05-01T17:40:26.960+0300] {subprocess.py:93} INFO - [0m14:40:26  adapter type: postgres
[2024-05-01T17:40:26.961+0300] {subprocess.py:93} INFO - [0m14:40:26  adapter version: 1.7.13
[2024-05-01T17:40:26.962+0300] {subprocess.py:93} INFO - [0m14:40:26  Configuration:
[2024-05-01T17:40:26.965+0300] {subprocess.py:93} INFO - [0m14:40:26    profiles.yml file [[32mOK found and valid[0m]
[2024-05-01T17:40:26.968+0300] {subprocess.py:93} INFO - [0m14:40:26    dbt_project.yml file [[31mERROR not found[0m]
[2024-05-01T17:40:26.973+0300] {subprocess.py:93} INFO - [0m14:40:26  Required dependencies:
[2024-05-01T17:40:28.740+0300] {subprocess.py:93} INFO - [0m14:40:28   - git [[32mOK found[0m]
[2024-05-01T17:40:28.740+0300] {subprocess.py:93} INFO - 
[2024-05-01T17:40:28.759+0300] {subprocess.py:93} INFO - [0m14:40:28  Connection:
[2024-05-01T17:40:28.776+0300] {subprocess.py:93} INFO - [0m14:40:28    host: localhost
[2024-05-01T17:40:28.787+0300] {subprocess.py:93} INFO - [0m14:40:28    port: 5432
[2024-05-01T17:40:28.803+0300] {subprocess.py:93} INFO - [0m14:40:28    user: postgres
[2024-05-01T17:40:28.806+0300] {subprocess.py:93} INFO - [0m14:40:28    database: traffic
[2024-05-01T17:40:28.820+0300] {subprocess.py:93} INFO - [0m14:40:28    schema: traffic_schema
[2024-05-01T17:40:28.821+0300] {subprocess.py:93} INFO - [0m14:40:28    connect_timeout: 10
[2024-05-01T17:40:28.823+0300] {subprocess.py:93} INFO - [0m14:40:28    role: None
[2024-05-01T17:40:28.845+0300] {subprocess.py:93} INFO - [0m14:40:28    search_path: None
[2024-05-01T17:40:28.847+0300] {subprocess.py:93} INFO - [0m14:40:28    keepalives_idle: 0
[2024-05-01T17:40:28.848+0300] {subprocess.py:93} INFO - [0m14:40:28    sslmode: None
[2024-05-01T17:40:28.864+0300] {subprocess.py:93} INFO - [0m14:40:28    sslcert: None
[2024-05-01T17:40:28.868+0300] {subprocess.py:93} INFO - [0m14:40:28    sslkey: None
[2024-05-01T17:40:28.870+0300] {subprocess.py:93} INFO - [0m14:40:28    sslrootcert: None
[2024-05-01T17:40:28.873+0300] {subprocess.py:93} INFO - [0m14:40:28    application_name: dbt
[2024-05-01T17:40:28.875+0300] {subprocess.py:93} INFO - [0m14:40:28    retries: 1
[2024-05-01T17:40:28.876+0300] {subprocess.py:93} INFO - [0m14:40:28  Registered adapter: postgres=1.7.13
[2024-05-01T17:40:29.092+0300] {subprocess.py:93} INFO - [0m14:40:29    Connection test: [[32mOK connection ok[0m]
[2024-05-01T17:40:29.093+0300] {subprocess.py:93} INFO - 
[2024-05-01T17:40:29.097+0300] {subprocess.py:93} INFO - [0m14:40:29  [31m1 check failed:[0m
[2024-05-01T17:40:29.100+0300] {subprocess.py:93} INFO - [0m14:40:29  Project loading failed for the following reason:
[2024-05-01T17:40:29.101+0300] {subprocess.py:93} INFO -  project path </tmp/airflowtmpxwlh0su8/dbt_project.yml> not found
[2024-05-01T17:40:29.101+0300] {subprocess.py:93} INFO - 
[2024-05-01T17:40:34.798+0300] {subprocess.py:97} INFO - Command exited with return code 1
[2024-05-01T17:40:35.214+0300] {taskinstance.py:441} INFO - ::group::Post task execution logs
[2024-05-01T17:40:47.788+0300] {taskinstance.py:2890} ERROR - Task failed with exception
Traceback (most recent call last):
  File "/home/yohanes/Documents/10academy/week2_2/10ac_city_traffic_data_warehouse_week2/week2_env/lib/python3.8/site-packages/airflow/models/taskinstance.py", line 465, in _execute_task
    result = _execute_callable(context=context, **execute_callable_kwargs)
  File "/home/yohanes/Documents/10academy/week2_2/10ac_city_traffic_data_warehouse_week2/week2_env/lib/python3.8/site-packages/airflow/models/taskinstance.py", line 432, in _execute_callable
    return execute_callable(context=context, **execute_callable_kwargs)
  File "/home/yohanes/Documents/10academy/week2_2/10ac_city_traffic_data_warehouse_week2/week2_env/lib/python3.8/site-packages/airflow/models/baseoperator.py", line 400, in wrapper
    return func(self, *args, **kwargs)
  File "/home/yohanes/Documents/10academy/week2_2/10ac_city_traffic_data_warehouse_week2/week2_env/lib/python3.8/site-packages/airflow/operators/bash.py", line 243, in execute
    raise AirflowException(
airflow.exceptions.AirflowException: Bash command failed. The command returned a non-zero exit code 1.
[2024-05-01T17:40:50.493+0300] {taskinstance.py:1205} INFO - Marking task as UP_FOR_RETRY. dag_id=dbt_dag, task_id=dbt_debug, execution_date=20240501T130412, start_date=20240501T143634, end_date=20240501T144049
[2024-05-01T17:40:58.442+0300] {standard_task_runner.py:110} ERROR - Failed to execute job 38 for task dbt_debug (Bash command failed. The command returned a non-zero exit code 1.; 7951)
[2024-05-01T17:40:58.577+0300] {local_task_job_runner.py:240} INFO - Task exited with return code 1
[2024-05-01T17:40:59.009+0300] {taskinstance.py:3482} INFO - 0 downstream tasks scheduled from follow-on schedule check
[2024-05-01T17:40:59.160+0300] {local_task_job_runner.py:222} INFO - ::endgroup::
