[2024-05-01T17:46:08.243+0300] {local_task_job_runner.py:120} INFO - ::group::Pre task execution logs
[2024-05-01T17:46:12.035+0300] {taskinstance.py:2073} INFO - Dependencies all met for dep_context=non-requeueable deps ti=<TaskInstance: dbt_dag.dbt_debug manual__2024-05-01T13:04:12.949516+00:00 [queued]>
[2024-05-01T17:46:12.850+0300] {taskinstance.py:2073} INFO - Dependencies all met for dep_context=requeueable deps ti=<TaskInstance: dbt_dag.dbt_debug manual__2024-05-01T13:04:12.949516+00:00 [queued]>
[2024-05-01T17:46:12.850+0300] {taskinstance.py:2303} INFO - Starting attempt 4 of 4
[2024-05-01T17:46:35.521+0300] {taskinstance.py:2327} INFO - Executing <Task(BashOperator): dbt_debug> on 2024-05-01 13:04:12.949516+00:00
[2024-05-01T17:46:35.527+0300] {standard_task_runner.py:63} INFO - Started process 17862 to run task
[2024-05-01T17:46:35.535+0300] {standard_task_runner.py:90} INFO - Running: ['airflow', 'tasks', 'run', 'dbt_dag', 'dbt_debug', 'manual__2024-05-01T13:04:12.949516+00:00', '--job-id', '57', '--raw', '--subdir', 'DAGS_FOLDER/bash.py', '--cfg-path', '/tmp/tmp_tl64_vv']
[2024-05-01T17:46:35.540+0300] {standard_task_runner.py:91} INFO - Job 57: Subtask dbt_debug
[2024-05-01T17:46:35.704+0300] {task_command.py:426} INFO - Running <TaskInstance: dbt_dag.dbt_debug manual__2024-05-01T13:04:12.949516+00:00 [running]> on host yohanes-Satellite-Pro-C50-A363
[2024-05-01T17:46:35.958+0300] {taskinstance.py:2644} INFO - Exporting env vars: AIRFLOW_CTX_DAG_OWNER='airflow' AIRFLOW_CTX_DAG_ID='dbt_dag' AIRFLOW_CTX_TASK_ID='dbt_debug' AIRFLOW_CTX_EXECUTION_DATE='2024-05-01T13:04:12.949516+00:00' AIRFLOW_CTX_TRY_NUMBER='4' AIRFLOW_CTX_DAG_RUN_ID='manual__2024-05-01T13:04:12.949516+00:00'
[2024-05-01T17:46:35.959+0300] {taskinstance.py:430} INFO - ::endgroup::
[2024-05-01T17:46:35.988+0300] {subprocess.py:63} INFO - Tmp dir root location: /tmp
[2024-05-01T17:46:35.989+0300] {subprocess.py:75} INFO - Running command: ['/usr/bin/bash', '-c', 'dbt debug']
[2024-05-01T17:46:36.002+0300] {subprocess.py:86} INFO - Output:
[2024-05-01T17:46:42.935+0300] {subprocess.py:93} INFO - [0m14:46:42  Running with dbt=1.7.13
[2024-05-01T17:46:42.940+0300] {subprocess.py:93} INFO - [0m14:46:42  dbt version: 1.7.13
[2024-05-01T17:46:42.941+0300] {subprocess.py:93} INFO - [0m14:46:42  python version: 3.8.10
[2024-05-01T17:46:42.943+0300] {subprocess.py:93} INFO - [0m14:46:42  python path: /home/yohanes/Documents/10academy/week2_2/10ac_city_traffic_data_warehouse_week2/week2_env/bin/python3
[2024-05-01T17:46:42.944+0300] {subprocess.py:93} INFO - [0m14:46:42  os info: Linux-5.15.0-105-generic-x86_64-with-glibc2.29
[2024-05-01T17:46:43.143+0300] {subprocess.py:93} INFO - [0m14:46:43  Using profiles dir at /home/yohanes/.dbt
[2024-05-01T17:46:43.145+0300] {subprocess.py:93} INFO - [0m14:46:43  Using profiles.yml file at /home/yohanes/.dbt/profiles.yml
[2024-05-01T17:46:43.146+0300] {subprocess.py:93} INFO - [0m14:46:43  Using dbt_project.yml file at /tmp/airflowtmpyz5n9x70/dbt_project.yml
[2024-05-01T17:46:43.148+0300] {subprocess.py:93} INFO - [0m14:46:43  adapter type: postgres
[2024-05-01T17:46:43.149+0300] {subprocess.py:93} INFO - [0m14:46:43  adapter version: 1.7.13
[2024-05-01T17:46:43.151+0300] {subprocess.py:93} INFO - [0m14:46:43  Configuration:
[2024-05-01T17:46:43.153+0300] {subprocess.py:93} INFO - [0m14:46:43    profiles.yml file [[32mOK found and valid[0m]
[2024-05-01T17:46:43.154+0300] {subprocess.py:93} INFO - [0m14:46:43    dbt_project.yml file [[31mERROR not found[0m]
[2024-05-01T17:46:43.156+0300] {subprocess.py:93} INFO - [0m14:46:43  Required dependencies:
[2024-05-01T17:46:43.171+0300] {subprocess.py:93} INFO - [0m14:46:43   - git [[32mOK found[0m]
[2024-05-01T17:46:43.171+0300] {subprocess.py:93} INFO - 
[2024-05-01T17:46:43.172+0300] {subprocess.py:93} INFO - [0m14:46:43  Connection:
[2024-05-01T17:46:43.173+0300] {subprocess.py:93} INFO - [0m14:46:43    host: localhost
[2024-05-01T17:46:43.175+0300] {subprocess.py:93} INFO - [0m14:46:43    port: 5432
[2024-05-01T17:46:43.176+0300] {subprocess.py:93} INFO - [0m14:46:43    user: postgres
[2024-05-01T17:46:43.177+0300] {subprocess.py:93} INFO - [0m14:46:43    database: traffic
[2024-05-01T17:46:43.179+0300] {subprocess.py:93} INFO - [0m14:46:43    schema: traffic_schema
[2024-05-01T17:46:43.180+0300] {subprocess.py:93} INFO - [0m14:46:43    connect_timeout: 10
[2024-05-01T17:46:43.181+0300] {subprocess.py:93} INFO - [0m14:46:43    role: None
[2024-05-01T17:46:43.182+0300] {subprocess.py:93} INFO - [0m14:46:43    search_path: None
[2024-05-01T17:46:43.184+0300] {subprocess.py:93} INFO - [0m14:46:43    keepalives_idle: 0
[2024-05-01T17:46:43.185+0300] {subprocess.py:93} INFO - [0m14:46:43    sslmode: None
[2024-05-01T17:46:43.186+0300] {subprocess.py:93} INFO - [0m14:46:43    sslcert: None
[2024-05-01T17:46:43.187+0300] {subprocess.py:93} INFO - [0m14:46:43    sslkey: None
[2024-05-01T17:46:43.189+0300] {subprocess.py:93} INFO - [0m14:46:43    sslrootcert: None
[2024-05-01T17:46:43.190+0300] {subprocess.py:93} INFO - [0m14:46:43    application_name: dbt
[2024-05-01T17:46:43.191+0300] {subprocess.py:93} INFO - [0m14:46:43    retries: 1
[2024-05-01T17:46:43.192+0300] {subprocess.py:93} INFO - [0m14:46:43  Registered adapter: postgres=1.7.13
[2024-05-01T17:46:43.225+0300] {subprocess.py:93} INFO - [0m14:46:43    Connection test: [[32mOK connection ok[0m]
[2024-05-01T17:46:43.226+0300] {subprocess.py:93} INFO - 
[2024-05-01T17:46:43.227+0300] {subprocess.py:93} INFO - [0m14:46:43  [31m1 check failed:[0m
[2024-05-01T17:46:43.229+0300] {subprocess.py:93} INFO - [0m14:46:43  Project loading failed for the following reason:
[2024-05-01T17:46:43.229+0300] {subprocess.py:93} INFO -  project path </tmp/airflowtmpyz5n9x70/dbt_project.yml> not found
[2024-05-01T17:46:43.229+0300] {subprocess.py:93} INFO - 
[2024-05-01T17:46:44.701+0300] {subprocess.py:97} INFO - Command exited with return code 1
[2024-05-01T17:46:44.702+0300] {taskinstance.py:441} INFO - ::group::Post task execution logs
[2024-05-01T17:46:44.737+0300] {taskinstance.py:2890} ERROR - Task failed with exception
Traceback (most recent call last):
  File "/home/yohanes/Documents/10academy/week2_2/10ac_city_traffic_data_warehouse_week2/week2_env/lib/python3.8/site-packages/airflow/models/taskinstance.py", line 465, in _execute_task
    result = _execute_callable(context=context, **execute_callable_kwargs)
  File "/home/yohanes/Documents/10academy/week2_2/10ac_city_traffic_data_warehouse_week2/week2_env/lib/python3.8/site-packages/airflow/models/taskinstance.py", line 432, in _execute_callable
    return execute_callable(context=context, **execute_callable_kwargs)
  File "/home/yohanes/Documents/10academy/week2_2/10ac_city_traffic_data_warehouse_week2/week2_env/lib/python3.8/site-packages/airflow/models/baseoperator.py", line 400, in wrapper
    return func(self, *args, **kwargs)
  File "/home/yohanes/Documents/10academy/week2_2/10ac_city_traffic_data_warehouse_week2/week2_env/lib/python3.8/site-packages/airflow/operators/bash.py", line 243, in execute
    raise AirflowException(
airflow.exceptions.AirflowException: Bash command failed. The command returned a non-zero exit code 1.
[2024-05-01T17:46:44.743+0300] {taskinstance.py:1205} INFO - Marking task as FAILED. dag_id=dbt_dag, task_id=dbt_debug, execution_date=20240501T130412, start_date=20240501T144612, end_date=20240501T144644
[2024-05-01T17:46:44.866+0300] {standard_task_runner.py:110} ERROR - Failed to execute job 57 for task dbt_debug (Bash command failed. The command returned a non-zero exit code 1.; 17862)
[2024-05-01T17:46:44.875+0300] {local_task_job_runner.py:240} INFO - Task exited with return code 1
[2024-05-01T17:46:44.914+0300] {taskinstance.py:3482} INFO - 0 downstream tasks scheduled from follow-on schedule check
[2024-05-01T17:46:45.132+0300] {local_task_job_runner.py:222} INFO - ::endgroup::
