[2024-05-01T18:12:09.502+0300] {local_task_job_runner.py:120} INFO - ::group::Pre task execution logs
[2024-05-01T18:12:09.554+0300] {taskinstance.py:2073} INFO - Dependencies all met for dep_context=non-requeueable deps ti=<TaskInstance: dbt_dag.dbt_debug manual__2024-05-01T14:56:27.208209+00:00 [queued]>
[2024-05-01T18:12:09.569+0300] {taskinstance.py:2073} INFO - Dependencies all met for dep_context=requeueable deps ti=<TaskInstance: dbt_dag.dbt_debug manual__2024-05-01T14:56:27.208209+00:00 [queued]>
[2024-05-01T18:12:09.569+0300] {taskinstance.py:2303} INFO - Starting attempt 4 of 4
[2024-05-01T18:12:09.760+0300] {taskinstance.py:2327} INFO - Executing <Task(BashOperator): dbt_debug> on 2024-05-01 14:56:27.208209+00:00
[2024-05-01T18:12:09.766+0300] {standard_task_runner.py:63} INFO - Started process 40558 to run task
[2024-05-01T18:12:09.771+0300] {standard_task_runner.py:90} INFO - Running: ['airflow', 'tasks', 'run', 'dbt_dag', 'dbt_debug', 'manual__2024-05-01T14:56:27.208209+00:00', '--job-id', '66', '--raw', '--subdir', 'DAGS_FOLDER/bash.py', '--cfg-path', '/tmp/tmphm57qwhx']
[2024-05-01T18:12:09.774+0300] {standard_task_runner.py:91} INFO - Job 66: Subtask dbt_debug
[2024-05-01T18:12:09.904+0300] {task_command.py:426} INFO - Running <TaskInstance: dbt_dag.dbt_debug manual__2024-05-01T14:56:27.208209+00:00 [running]> on host yohanes-Satellite-Pro-C50-A363
[2024-05-01T18:12:10.111+0300] {taskinstance.py:2644} INFO - Exporting env vars: AIRFLOW_CTX_DAG_OWNER='airflow' AIRFLOW_CTX_DAG_ID='dbt_dag' AIRFLOW_CTX_TASK_ID='dbt_debug' AIRFLOW_CTX_EXECUTION_DATE='2024-05-01T14:56:27.208209+00:00' AIRFLOW_CTX_TRY_NUMBER='4' AIRFLOW_CTX_DAG_RUN_ID='manual__2024-05-01T14:56:27.208209+00:00'
[2024-05-01T18:12:10.112+0300] {taskinstance.py:430} INFO - ::endgroup::
[2024-05-01T18:12:10.140+0300] {subprocess.py:63} INFO - Tmp dir root location: /tmp
[2024-05-01T18:12:10.141+0300] {subprocess.py:75} INFO - Running command: ['/usr/bin/bash', '-c', 'dbt debug']
[2024-05-01T18:12:10.151+0300] {subprocess.py:86} INFO - Output:
[2024-05-01T18:12:15.926+0300] {subprocess.py:93} INFO - [0m15:12:15  Running with dbt=1.7.13
[2024-05-01T18:12:15.929+0300] {subprocess.py:93} INFO - [0m15:12:15  dbt version: 1.7.13
[2024-05-01T18:12:15.930+0300] {subprocess.py:93} INFO - [0m15:12:15  python version: 3.8.10
[2024-05-01T18:12:15.931+0300] {subprocess.py:93} INFO - [0m15:12:15  python path: /home/yohanes/Documents/10academy/week2_2/10ac_city_traffic_data_warehouse_week2/week2_env/bin/python3
[2024-05-01T18:12:15.932+0300] {subprocess.py:93} INFO - [0m15:12:15  os info: Linux-5.15.0-105-generic-x86_64-with-glibc2.29
[2024-05-01T18:12:16.113+0300] {subprocess.py:93} INFO - [0m15:12:16  Using profiles dir at /home/yohanes/.dbt
[2024-05-01T18:12:16.114+0300] {subprocess.py:93} INFO - [0m15:12:16  Using profiles.yml file at /home/yohanes/.dbt/profiles.yml
[2024-05-01T18:12:16.115+0300] {subprocess.py:93} INFO - [0m15:12:16  Using dbt_project.yml file at /tmp/airflowtmpt5kkskj9/dbt_project.yml
[2024-05-01T18:12:16.117+0300] {subprocess.py:93} INFO - [0m15:12:16  adapter type: postgres
[2024-05-01T18:12:16.119+0300] {subprocess.py:93} INFO - [0m15:12:16  adapter version: 1.7.13
[2024-05-01T18:12:16.120+0300] {subprocess.py:93} INFO - [0m15:12:16  Configuration:
[2024-05-01T18:12:16.122+0300] {subprocess.py:93} INFO - [0m15:12:16    profiles.yml file [[32mOK found and valid[0m]
[2024-05-01T18:12:16.123+0300] {subprocess.py:93} INFO - [0m15:12:16    dbt_project.yml file [[31mERROR not found[0m]
[2024-05-01T18:12:16.123+0300] {subprocess.py:93} INFO - [0m15:12:16  Required dependencies:
[2024-05-01T18:12:16.139+0300] {subprocess.py:93} INFO - [0m15:12:16   - git [[32mOK found[0m]
[2024-05-01T18:12:16.140+0300] {subprocess.py:93} INFO - 
[2024-05-01T18:12:16.140+0300] {subprocess.py:93} INFO - [0m15:12:16  Connection:
[2024-05-01T18:12:16.142+0300] {subprocess.py:93} INFO - [0m15:12:16    host: localhost
[2024-05-01T18:12:16.143+0300] {subprocess.py:93} INFO - [0m15:12:16    port: 5432
[2024-05-01T18:12:16.144+0300] {subprocess.py:93} INFO - [0m15:12:16    user: postgres
[2024-05-01T18:12:16.145+0300] {subprocess.py:93} INFO - [0m15:12:16    database: traffic
[2024-05-01T18:12:16.146+0300] {subprocess.py:93} INFO - [0m15:12:16    schema: traffic_schema
[2024-05-01T18:12:16.147+0300] {subprocess.py:93} INFO - [0m15:12:16    connect_timeout: 10
[2024-05-01T18:12:16.149+0300] {subprocess.py:93} INFO - [0m15:12:16    role: None
[2024-05-01T18:12:16.150+0300] {subprocess.py:93} INFO - [0m15:12:16    search_path: None
[2024-05-01T18:12:16.152+0300] {subprocess.py:93} INFO - [0m15:12:16    keepalives_idle: 0
[2024-05-01T18:12:16.153+0300] {subprocess.py:93} INFO - [0m15:12:16    sslmode: None
[2024-05-01T18:12:16.155+0300] {subprocess.py:93} INFO - [0m15:12:16    sslcert: None
[2024-05-01T18:12:16.156+0300] {subprocess.py:93} INFO - [0m15:12:16    sslkey: None
[2024-05-01T18:12:16.158+0300] {subprocess.py:93} INFO - [0m15:12:16    sslrootcert: None
[2024-05-01T18:12:16.159+0300] {subprocess.py:93} INFO - [0m15:12:16    application_name: dbt
[2024-05-01T18:12:16.160+0300] {subprocess.py:93} INFO - [0m15:12:16    retries: 1
[2024-05-01T18:12:16.161+0300] {subprocess.py:93} INFO - [0m15:12:16  Registered adapter: postgres=1.7.13
[2024-05-01T18:12:16.201+0300] {subprocess.py:93} INFO - [0m15:12:16    Connection test: [[32mOK connection ok[0m]
[2024-05-01T18:12:16.202+0300] {subprocess.py:93} INFO - 
[2024-05-01T18:12:16.203+0300] {subprocess.py:93} INFO - [0m15:12:16  [31m1 check failed:[0m
[2024-05-01T18:12:16.205+0300] {subprocess.py:93} INFO - [0m15:12:16  Project loading failed for the following reason:
[2024-05-01T18:12:16.206+0300] {subprocess.py:93} INFO -  project path </tmp/airflowtmpt5kkskj9/dbt_project.yml> not found
[2024-05-01T18:12:16.206+0300] {subprocess.py:93} INFO - 
[2024-05-01T18:12:19.333+0300] {subprocess.py:97} INFO - Command exited with return code 1
[2024-05-01T18:12:19.335+0300] {taskinstance.py:441} INFO - ::group::Post task execution logs
[2024-05-01T18:12:19.367+0300] {taskinstance.py:2890} ERROR - Task failed with exception
Traceback (most recent call last):
  File "/home/yohanes/Documents/10academy/week2_2/10ac_city_traffic_data_warehouse_week2/week2_env/lib/python3.8/site-packages/airflow/models/taskinstance.py", line 465, in _execute_task
    result = _execute_callable(context=context, **execute_callable_kwargs)
  File "/home/yohanes/Documents/10academy/week2_2/10ac_city_traffic_data_warehouse_week2/week2_env/lib/python3.8/site-packages/airflow/models/taskinstance.py", line 432, in _execute_callable
    return execute_callable(context=context, **execute_callable_kwargs)
  File "/home/yohanes/Documents/10academy/week2_2/10ac_city_traffic_data_warehouse_week2/week2_env/lib/python3.8/site-packages/airflow/models/baseoperator.py", line 400, in wrapper
    return func(self, *args, **kwargs)
  File "/home/yohanes/Documents/10academy/week2_2/10ac_city_traffic_data_warehouse_week2/week2_env/lib/python3.8/site-packages/airflow/operators/bash.py", line 243, in execute
    raise AirflowException(
airflow.exceptions.AirflowException: Bash command failed. The command returned a non-zero exit code 1.
[2024-05-01T18:12:19.372+0300] {taskinstance.py:1205} INFO - Marking task as FAILED. dag_id=dbt_dag, task_id=dbt_debug, execution_date=20240501T145627, start_date=20240501T151209, end_date=20240501T151219
[2024-05-01T18:12:19.439+0300] {standard_task_runner.py:110} ERROR - Failed to execute job 66 for task dbt_debug (Bash command failed. The command returned a non-zero exit code 1.; 40558)
[2024-05-01T18:12:19.465+0300] {local_task_job_runner.py:240} INFO - Task exited with return code 1
[2024-05-01T18:12:19.522+0300] {taskinstance.py:3482} INFO - 0 downstream tasks scheduled from follow-on schedule check
[2024-05-01T18:12:19.538+0300] {local_task_job_runner.py:222} INFO - ::endgroup::
