[2024-05-01T17:45:41.185+0300] {local_task_job_runner.py:120} INFO - ::group::Pre task execution logs
[2024-05-01T17:45:41.343+0300] {taskinstance.py:2073} INFO - Dependencies all met for dep_context=non-requeueable deps ti=<TaskInstance: dbt_dag.dbt_debug manual__2024-05-01T12:34:54.560122+00:00 [queued]>
[2024-05-01T17:45:41.377+0300] {taskinstance.py:2073} INFO - Dependencies all met for dep_context=requeueable deps ti=<TaskInstance: dbt_dag.dbt_debug manual__2024-05-01T12:34:54.560122+00:00 [queued]>
[2024-05-01T17:45:41.378+0300] {taskinstance.py:2303} INFO - Starting attempt 4 of 4
[2024-05-01T17:45:41.958+0300] {taskinstance.py:2327} INFO - Executing <Task(BashOperator): dbt_debug> on 2024-05-01 12:34:54.560122+00:00
[2024-05-01T17:45:41.965+0300] {standard_task_runner.py:63} INFO - Started process 14996 to run task
[2024-05-01T17:45:41.980+0300] {standard_task_runner.py:90} INFO - Running: ['airflow', 'tasks', 'run', 'dbt_dag', 'dbt_debug', 'manual__2024-05-01T12:34:54.560122+00:00', '--job-id', '49', '--raw', '--subdir', 'DAGS_FOLDER/bash.py', '--cfg-path', '/tmp/tmpzocey87t']
[2024-05-01T17:45:41.986+0300] {standard_task_runner.py:91} INFO - Job 49: Subtask dbt_debug
[2024-05-01T17:45:42.386+0300] {task_command.py:426} INFO - Running <TaskInstance: dbt_dag.dbt_debug manual__2024-05-01T12:34:54.560122+00:00 [running]> on host yohanes-Satellite-Pro-C50-A363
[2024-05-01T17:45:42.971+0300] {taskinstance.py:2644} INFO - Exporting env vars: AIRFLOW_CTX_DAG_OWNER='airflow' AIRFLOW_CTX_DAG_ID='dbt_dag' AIRFLOW_CTX_TASK_ID='dbt_debug' AIRFLOW_CTX_EXECUTION_DATE='2024-05-01T12:34:54.560122+00:00' AIRFLOW_CTX_TRY_NUMBER='4' AIRFLOW_CTX_DAG_RUN_ID='manual__2024-05-01T12:34:54.560122+00:00'
[2024-05-01T17:45:42.972+0300] {taskinstance.py:430} INFO - ::endgroup::
[2024-05-01T17:45:43.037+0300] {subprocess.py:63} INFO - Tmp dir root location: /tmp
[2024-05-01T17:45:43.038+0300] {subprocess.py:75} INFO - Running command: ['/usr/bin/bash', '-c', 'dbt debug']
[2024-05-01T17:45:43.059+0300] {subprocess.py:86} INFO - Output:
[2024-05-01T17:46:09.693+0300] {subprocess.py:93} INFO - [0m14:46:09  Running with dbt=1.7.13
[2024-05-01T17:46:09.704+0300] {subprocess.py:93} INFO - [0m14:46:09  dbt version: 1.7.13
[2024-05-01T17:46:09.714+0300] {subprocess.py:93} INFO - [0m14:46:09  python version: 3.8.10
[2024-05-01T17:46:09.718+0300] {subprocess.py:93} INFO - [0m14:46:09  python path: /home/yohanes/Documents/10academy/week2_2/10ac_city_traffic_data_warehouse_week2/week2_env/bin/python3
[2024-05-01T17:46:09.725+0300] {subprocess.py:93} INFO - [0m14:46:09  os info: Linux-5.15.0-105-generic-x86_64-with-glibc2.29
[2024-05-01T17:46:14.638+0300] {subprocess.py:93} INFO - [0m14:46:14  Using profiles dir at /home/yohanes/.dbt
[2024-05-01T17:46:14.733+0300] {subprocess.py:93} INFO - [0m14:46:14  Using profiles.yml file at /home/yohanes/.dbt/profiles.yml
[2024-05-01T17:46:14.734+0300] {subprocess.py:93} INFO - [0m14:46:14  Using dbt_project.yml file at /tmp/airflowtmpswsdds0c/dbt_project.yml
[2024-05-01T17:46:14.734+0300] {subprocess.py:93} INFO - [0m14:46:14  adapter type: postgres
[2024-05-01T17:46:14.735+0300] {subprocess.py:93} INFO - [0m14:46:14  adapter version: 1.7.13
[2024-05-01T17:46:14.735+0300] {subprocess.py:93} INFO - [0m14:46:14  Configuration:
[2024-05-01T17:46:14.735+0300] {subprocess.py:93} INFO - [0m14:46:14    profiles.yml file [[32mOK found and valid[0m]
[2024-05-01T17:46:14.736+0300] {subprocess.py:93} INFO - [0m14:46:14    dbt_project.yml file [[31mERROR not found[0m]
[2024-05-01T17:46:14.737+0300] {subprocess.py:93} INFO - [0m14:46:14  Required dependencies:
[2024-05-01T17:46:15.494+0300] {subprocess.py:93} INFO - [0m14:46:15   - git [[32mOK found[0m]
[2024-05-01T17:46:15.495+0300] {subprocess.py:93} INFO - 
[2024-05-01T17:46:15.501+0300] {subprocess.py:93} INFO - [0m14:46:15  Connection:
[2024-05-01T17:46:15.510+0300] {subprocess.py:93} INFO - [0m14:46:15    host: localhost
[2024-05-01T17:46:15.518+0300] {subprocess.py:93} INFO - [0m14:46:15    port: 5432
[2024-05-01T17:46:15.531+0300] {subprocess.py:93} INFO - [0m14:46:15    user: postgres
[2024-05-01T17:46:15.541+0300] {subprocess.py:93} INFO - [0m14:46:15    database: traffic
[2024-05-01T17:46:15.546+0300] {subprocess.py:93} INFO - [0m14:46:15    schema: traffic_schema
[2024-05-01T17:46:15.553+0300] {subprocess.py:93} INFO - [0m14:46:15    connect_timeout: 10
[2024-05-01T17:46:15.560+0300] {subprocess.py:93} INFO - [0m14:46:15    role: None
[2024-05-01T17:46:15.569+0300] {subprocess.py:93} INFO - [0m14:46:15    search_path: None
[2024-05-01T17:46:15.578+0300] {subprocess.py:93} INFO - [0m14:46:15    keepalives_idle: 0
[2024-05-01T17:46:15.583+0300] {subprocess.py:93} INFO - [0m14:46:15    sslmode: None
[2024-05-01T17:46:15.587+0300] {subprocess.py:93} INFO - [0m14:46:15    sslcert: None
[2024-05-01T17:46:15.594+0300] {subprocess.py:93} INFO - [0m14:46:15    sslkey: None
[2024-05-01T17:46:15.606+0300] {subprocess.py:93} INFO - [0m14:46:15    sslrootcert: None
[2024-05-01T17:46:15.611+0300] {subprocess.py:93} INFO - [0m14:46:15    application_name: dbt
[2024-05-01T17:46:15.618+0300] {subprocess.py:93} INFO - [0m14:46:15    retries: 1
[2024-05-01T17:46:15.628+0300] {subprocess.py:93} INFO - [0m14:46:15  Registered adapter: postgres=1.7.13
[2024-05-01T17:46:15.941+0300] {subprocess.py:93} INFO - [0m14:46:15    Connection test: [[32mOK connection ok[0m]
[2024-05-01T17:46:15.941+0300] {subprocess.py:93} INFO - 
[2024-05-01T17:46:15.944+0300] {subprocess.py:93} INFO - [0m14:46:15  [31m1 check failed:[0m
[2024-05-01T17:46:15.950+0300] {subprocess.py:93} INFO - [0m14:46:15  Project loading failed for the following reason:
[2024-05-01T17:46:15.951+0300] {subprocess.py:93} INFO -  project path </tmp/airflowtmpswsdds0c/dbt_project.yml> not found
[2024-05-01T17:46:15.951+0300] {subprocess.py:93} INFO - 
[2024-05-01T17:46:19.995+0300] {subprocess.py:97} INFO - Command exited with return code 1
[2024-05-01T17:46:20.014+0300] {taskinstance.py:441} INFO - ::group::Post task execution logs
[2024-05-01T17:46:20.122+0300] {taskinstance.py:2890} ERROR - Task failed with exception
Traceback (most recent call last):
  File "/home/yohanes/Documents/10academy/week2_2/10ac_city_traffic_data_warehouse_week2/week2_env/lib/python3.8/site-packages/airflow/models/taskinstance.py", line 465, in _execute_task
    result = _execute_callable(context=context, **execute_callable_kwargs)
  File "/home/yohanes/Documents/10academy/week2_2/10ac_city_traffic_data_warehouse_week2/week2_env/lib/python3.8/site-packages/airflow/models/taskinstance.py", line 432, in _execute_callable
    return execute_callable(context=context, **execute_callable_kwargs)
  File "/home/yohanes/Documents/10academy/week2_2/10ac_city_traffic_data_warehouse_week2/week2_env/lib/python3.8/site-packages/airflow/models/baseoperator.py", line 400, in wrapper
    return func(self, *args, **kwargs)
  File "/home/yohanes/Documents/10academy/week2_2/10ac_city_traffic_data_warehouse_week2/week2_env/lib/python3.8/site-packages/airflow/operators/bash.py", line 243, in execute
    raise AirflowException(
airflow.exceptions.AirflowException: Bash command failed. The command returned a non-zero exit code 1.
[2024-05-01T17:46:20.151+0300] {taskinstance.py:1205} INFO - Marking task as FAILED. dag_id=dbt_dag, task_id=dbt_debug, execution_date=20240501T123454, start_date=20240501T144541, end_date=20240501T144620
[2024-05-01T17:46:21.042+0300] {standard_task_runner.py:110} ERROR - Failed to execute job 49 for task dbt_debug (Bash command failed. The command returned a non-zero exit code 1.; 14996)
[2024-05-01T17:46:21.074+0300] {local_task_job_runner.py:240} INFO - Task exited with return code 1
[2024-05-01T17:46:21.131+0300] {taskinstance.py:3482} INFO - 0 downstream tasks scheduled from follow-on schedule check
[2024-05-01T17:46:21.301+0300] {local_task_job_runner.py:222} INFO - ::endgroup::
