[2024-05-01T17:45:41.243+0300] {local_task_job_runner.py:120} INFO - ::group::Pre task execution logs
[2024-05-01T17:45:41.432+0300] {taskinstance.py:2073} INFO - Dependencies all met for dep_context=non-requeueable deps ti=<TaskInstance: dbt_dag.dbt_debug manual__2024-05-01T13:04:39.799822+00:00 [queued]>
[2024-05-01T17:45:41.491+0300] {taskinstance.py:2073} INFO - Dependencies all met for dep_context=requeueable deps ti=<TaskInstance: dbt_dag.dbt_debug manual__2024-05-01T13:04:39.799822+00:00 [queued]>
[2024-05-01T17:45:41.492+0300] {taskinstance.py:2303} INFO - Starting attempt 4 of 4
[2024-05-01T17:45:42.236+0300] {taskinstance.py:2327} INFO - Executing <Task(BashOperator): dbt_debug> on 2024-05-01 13:04:39.799822+00:00
[2024-05-01T17:45:42.250+0300] {standard_task_runner.py:63} INFO - Started process 15026 to run task
[2024-05-01T17:45:42.308+0300] {standard_task_runner.py:90} INFO - Running: ['airflow', 'tasks', 'run', 'dbt_dag', 'dbt_debug', 'manual__2024-05-01T13:04:39.799822+00:00', '--job-id', '50', '--raw', '--subdir', 'DAGS_FOLDER/bash.py', '--cfg-path', '/tmp/tmpkh7o479r']
[2024-05-01T17:45:42.334+0300] {standard_task_runner.py:91} INFO - Job 50: Subtask dbt_debug
[2024-05-01T17:45:42.619+0300] {task_command.py:426} INFO - Running <TaskInstance: dbt_dag.dbt_debug manual__2024-05-01T13:04:39.799822+00:00 [running]> on host yohanes-Satellite-Pro-C50-A363
[2024-05-01T17:45:43.337+0300] {taskinstance.py:2644} INFO - Exporting env vars: AIRFLOW_CTX_DAG_OWNER='airflow' AIRFLOW_CTX_DAG_ID='dbt_dag' AIRFLOW_CTX_TASK_ID='dbt_debug' AIRFLOW_CTX_EXECUTION_DATE='2024-05-01T13:04:39.799822+00:00' AIRFLOW_CTX_TRY_NUMBER='4' AIRFLOW_CTX_DAG_RUN_ID='manual__2024-05-01T13:04:39.799822+00:00'
[2024-05-01T17:45:43.339+0300] {taskinstance.py:430} INFO - ::endgroup::
[2024-05-01T17:45:43.418+0300] {subprocess.py:63} INFO - Tmp dir root location: /tmp
[2024-05-01T17:45:43.424+0300] {subprocess.py:75} INFO - Running command: ['/usr/bin/bash', '-c', 'dbt debug']
[2024-05-01T17:45:43.460+0300] {subprocess.py:86} INFO - Output:
[2024-05-01T17:46:09.759+0300] {subprocess.py:93} INFO - [0m14:46:09  Running with dbt=1.7.13
[2024-05-01T17:46:09.778+0300] {subprocess.py:93} INFO - [0m14:46:09  dbt version: 1.7.13
[2024-05-01T17:46:09.796+0300] {subprocess.py:93} INFO - [0m14:46:09  python version: 3.8.10
[2024-05-01T17:46:09.806+0300] {subprocess.py:93} INFO - [0m14:46:09  python path: /home/yohanes/Documents/10academy/week2_2/10ac_city_traffic_data_warehouse_week2/week2_env/bin/python3
[2024-05-01T17:46:09.809+0300] {subprocess.py:93} INFO - [0m14:46:09  os info: Linux-5.15.0-105-generic-x86_64-with-glibc2.29
[2024-05-01T17:46:14.752+0300] {subprocess.py:93} INFO - [0m14:46:14  Using profiles dir at /home/yohanes/.dbt
[2024-05-01T17:46:14.788+0300] {subprocess.py:93} INFO - [0m14:46:14  Using profiles.yml file at /home/yohanes/.dbt/profiles.yml
[2024-05-01T17:46:14.789+0300] {subprocess.py:93} INFO - [0m14:46:14  Using dbt_project.yml file at /tmp/airflowtmpf95pby4x/dbt_project.yml
[2024-05-01T17:46:14.790+0300] {subprocess.py:93} INFO - [0m14:46:14  adapter type: postgres
[2024-05-01T17:46:14.790+0300] {subprocess.py:93} INFO - [0m14:46:14  adapter version: 1.7.13
[2024-05-01T17:46:14.790+0300] {subprocess.py:93} INFO - [0m14:46:14  Configuration:
[2024-05-01T17:46:14.791+0300] {subprocess.py:93} INFO - [0m14:46:14    profiles.yml file [[32mOK found and valid[0m]
[2024-05-01T17:46:14.791+0300] {subprocess.py:93} INFO - [0m14:46:14    dbt_project.yml file [[31mERROR not found[0m]
[2024-05-01T17:46:14.791+0300] {subprocess.py:93} INFO - [0m14:46:14  Required dependencies:
[2024-05-01T17:46:15.502+0300] {subprocess.py:93} INFO - [0m14:46:15   - git [[32mOK found[0m]
[2024-05-01T17:46:15.502+0300] {subprocess.py:93} INFO - 
[2024-05-01T17:46:15.508+0300] {subprocess.py:93} INFO - [0m14:46:15  Connection:
[2024-05-01T17:46:15.514+0300] {subprocess.py:93} INFO - [0m14:46:15    host: localhost
[2024-05-01T17:46:15.530+0300] {subprocess.py:93} INFO - [0m14:46:15    port: 5432
[2024-05-01T17:46:15.535+0300] {subprocess.py:93} INFO - [0m14:46:15    user: postgres
[2024-05-01T17:46:15.542+0300] {subprocess.py:93} INFO - [0m14:46:15    database: traffic
[2024-05-01T17:46:15.544+0300] {subprocess.py:93} INFO - [0m14:46:15    schema: traffic_schema
[2024-05-01T17:46:15.552+0300] {subprocess.py:93} INFO - [0m14:46:15    connect_timeout: 10
[2024-05-01T17:46:15.555+0300] {subprocess.py:93} INFO - [0m14:46:15    role: None
[2024-05-01T17:46:15.559+0300] {subprocess.py:93} INFO - [0m14:46:15    search_path: None
[2024-05-01T17:46:15.562+0300] {subprocess.py:93} INFO - [0m14:46:15    keepalives_idle: 0
[2024-05-01T17:46:15.568+0300] {subprocess.py:93} INFO - [0m14:46:15    sslmode: None
[2024-05-01T17:46:15.571+0300] {subprocess.py:93} INFO - [0m14:46:15    sslcert: None
[2024-05-01T17:46:15.576+0300] {subprocess.py:93} INFO - [0m14:46:15    sslkey: None
[2024-05-01T17:46:15.582+0300] {subprocess.py:93} INFO - [0m14:46:15    sslrootcert: None
[2024-05-01T17:46:15.584+0300] {subprocess.py:93} INFO - [0m14:46:15    application_name: dbt
[2024-05-01T17:46:15.587+0300] {subprocess.py:93} INFO - [0m14:46:15    retries: 1
[2024-05-01T17:46:15.595+0300] {subprocess.py:93} INFO - [0m14:46:15  Registered adapter: postgres=1.7.13
[2024-05-01T17:46:15.931+0300] {subprocess.py:93} INFO - [0m14:46:15    Connection test: [[32mOK connection ok[0m]
[2024-05-01T17:46:15.931+0300] {subprocess.py:93} INFO - 
[2024-05-01T17:46:15.947+0300] {subprocess.py:93} INFO - [0m14:46:15  [31m1 check failed:[0m
[2024-05-01T17:46:15.949+0300] {subprocess.py:93} INFO - [0m14:46:15  Project loading failed for the following reason:
[2024-05-01T17:46:15.950+0300] {subprocess.py:93} INFO -  project path </tmp/airflowtmpf95pby4x/dbt_project.yml> not found
[2024-05-01T17:46:15.950+0300] {subprocess.py:93} INFO - 
[2024-05-01T17:46:19.964+0300] {subprocess.py:97} INFO - Command exited with return code 1
[2024-05-01T17:46:19.966+0300] {taskinstance.py:441} INFO - ::group::Post task execution logs
[2024-05-01T17:46:20.012+0300] {taskinstance.py:2890} ERROR - Task failed with exception
Traceback (most recent call last):
  File "/home/yohanes/Documents/10academy/week2_2/10ac_city_traffic_data_warehouse_week2/week2_env/lib/python3.8/site-packages/airflow/models/taskinstance.py", line 465, in _execute_task
    result = _execute_callable(context=context, **execute_callable_kwargs)
  File "/home/yohanes/Documents/10academy/week2_2/10ac_city_traffic_data_warehouse_week2/week2_env/lib/python3.8/site-packages/airflow/models/taskinstance.py", line 432, in _execute_callable
    return execute_callable(context=context, **execute_callable_kwargs)
  File "/home/yohanes/Documents/10academy/week2_2/10ac_city_traffic_data_warehouse_week2/week2_env/lib/python3.8/site-packages/airflow/models/baseoperator.py", line 400, in wrapper
    return func(self, *args, **kwargs)
  File "/home/yohanes/Documents/10academy/week2_2/10ac_city_traffic_data_warehouse_week2/week2_env/lib/python3.8/site-packages/airflow/operators/bash.py", line 243, in execute
    raise AirflowException(
airflow.exceptions.AirflowException: Bash command failed. The command returned a non-zero exit code 1.
[2024-05-01T17:46:20.023+0300] {taskinstance.py:1205} INFO - Marking task as FAILED. dag_id=dbt_dag, task_id=dbt_debug, execution_date=20240501T130439, start_date=20240501T144541, end_date=20240501T144620
[2024-05-01T17:46:20.213+0300] {standard_task_runner.py:110} ERROR - Failed to execute job 50 for task dbt_debug (Bash command failed. The command returned a non-zero exit code 1.; 15026)
[2024-05-01T17:46:20.256+0300] {local_task_job_runner.py:240} INFO - Task exited with return code 1
[2024-05-01T17:46:20.522+0300] {taskinstance.py:3482} INFO - 0 downstream tasks scheduled from follow-on schedule check
[2024-05-01T17:46:20.701+0300] {local_task_job_runner.py:222} INFO - ::endgroup::
