[2024-05-01T17:55:39.454+0300] {local_task_job_runner.py:120} INFO - ::group::Pre task execution logs
[2024-05-01T17:55:39.509+0300] {taskinstance.py:2073} INFO - Dependencies all met for dep_context=non-requeueable deps ti=<TaskInstance: dbt_dag.dbt_debug manual__2024-05-01T14:44:52.332667+00:00 [queued]>
[2024-05-01T17:55:39.526+0300] {taskinstance.py:2073} INFO - Dependencies all met for dep_context=requeueable deps ti=<TaskInstance: dbt_dag.dbt_debug manual__2024-05-01T14:44:52.332667+00:00 [queued]>
[2024-05-01T17:55:39.526+0300] {taskinstance.py:2303} INFO - Starting attempt 3 of 4
[2024-05-01T17:55:39.737+0300] {taskinstance.py:2327} INFO - Executing <Task(BashOperator): dbt_debug> on 2024-05-01 14:44:52.332667+00:00
[2024-05-01T17:55:39.743+0300] {standard_task_runner.py:63} INFO - Started process 26148 to run task
[2024-05-01T17:55:39.747+0300] {standard_task_runner.py:90} INFO - Running: ['airflow', 'tasks', 'run', 'dbt_dag', 'dbt_debug', 'manual__2024-05-01T14:44:52.332667+00:00', '--job-id', '61', '--raw', '--subdir', 'DAGS_FOLDER/bash.py', '--cfg-path', '/tmp/tmp4xu0tlla']
[2024-05-01T17:55:39.751+0300] {standard_task_runner.py:91} INFO - Job 61: Subtask dbt_debug
[2024-05-01T17:55:39.885+0300] {task_command.py:426} INFO - Running <TaskInstance: dbt_dag.dbt_debug manual__2024-05-01T14:44:52.332667+00:00 [running]> on host yohanes-Satellite-Pro-C50-A363
[2024-05-01T17:55:40.133+0300] {taskinstance.py:2644} INFO - Exporting env vars: AIRFLOW_CTX_DAG_OWNER='airflow' AIRFLOW_CTX_DAG_ID='dbt_dag' AIRFLOW_CTX_TASK_ID='dbt_debug' AIRFLOW_CTX_EXECUTION_DATE='2024-05-01T14:44:52.332667+00:00' AIRFLOW_CTX_TRY_NUMBER='3' AIRFLOW_CTX_DAG_RUN_ID='manual__2024-05-01T14:44:52.332667+00:00'
[2024-05-01T17:55:40.135+0300] {taskinstance.py:430} INFO - ::endgroup::
[2024-05-01T17:55:40.161+0300] {subprocess.py:63} INFO - Tmp dir root location: /tmp
[2024-05-01T17:55:40.161+0300] {subprocess.py:75} INFO - Running command: ['/usr/bin/bash', '-c', 'dbt debug']
[2024-05-01T17:55:40.173+0300] {subprocess.py:86} INFO - Output:
[2024-05-01T17:55:44.856+0300] {subprocess.py:93} INFO - [0m14:55:44  Running with dbt=1.7.13
[2024-05-01T17:55:44.859+0300] {subprocess.py:93} INFO - [0m14:55:44  dbt version: 1.7.13
[2024-05-01T17:55:44.860+0300] {subprocess.py:93} INFO - [0m14:55:44  python version: 3.8.10
[2024-05-01T17:55:44.861+0300] {subprocess.py:93} INFO - [0m14:55:44  python path: /home/yohanes/Documents/10academy/week2_2/10ac_city_traffic_data_warehouse_week2/week2_env/bin/python3
[2024-05-01T17:55:44.863+0300] {subprocess.py:93} INFO - [0m14:55:44  os info: Linux-5.15.0-105-generic-x86_64-with-glibc2.29
[2024-05-01T17:55:45.061+0300] {subprocess.py:93} INFO - [0m14:55:45  Using profiles dir at /home/yohanes/.dbt
[2024-05-01T17:55:45.062+0300] {subprocess.py:93} INFO - [0m14:55:45  Using profiles.yml file at /home/yohanes/.dbt/profiles.yml
[2024-05-01T17:55:45.063+0300] {subprocess.py:93} INFO - [0m14:55:45  Using dbt_project.yml file at /tmp/airflowtmpxofrkscg/dbt_project.yml
[2024-05-01T17:55:45.065+0300] {subprocess.py:93} INFO - [0m14:55:45  adapter type: postgres
[2024-05-01T17:55:45.066+0300] {subprocess.py:93} INFO - [0m14:55:45  adapter version: 1.7.13
[2024-05-01T17:55:45.067+0300] {subprocess.py:93} INFO - [0m14:55:45  Configuration:
[2024-05-01T17:55:45.069+0300] {subprocess.py:93} INFO - [0m14:55:45    profiles.yml file [[32mOK found and valid[0m]
[2024-05-01T17:55:45.072+0300] {subprocess.py:93} INFO - [0m14:55:45    dbt_project.yml file [[31mERROR not found[0m]
[2024-05-01T17:55:45.074+0300] {subprocess.py:93} INFO - [0m14:55:45  Required dependencies:
[2024-05-01T17:55:45.092+0300] {subprocess.py:93} INFO - [0m14:55:45   - git [[32mOK found[0m]
[2024-05-01T17:55:45.092+0300] {subprocess.py:93} INFO - 
[2024-05-01T17:55:45.093+0300] {subprocess.py:93} INFO - [0m14:55:45  Connection:
[2024-05-01T17:55:45.096+0300] {subprocess.py:93} INFO - [0m14:55:45    host: localhost
[2024-05-01T17:55:45.097+0300] {subprocess.py:93} INFO - [0m14:55:45    port: 5432
[2024-05-01T17:55:45.097+0300] {subprocess.py:93} INFO - [0m14:55:45    user: postgres
[2024-05-01T17:55:45.098+0300] {subprocess.py:93} INFO - [0m14:55:45    database: traffic
[2024-05-01T17:55:45.099+0300] {subprocess.py:93} INFO - [0m14:55:45    schema: traffic_schema
[2024-05-01T17:55:45.100+0300] {subprocess.py:93} INFO - [0m14:55:45    connect_timeout: 10
[2024-05-01T17:55:45.102+0300] {subprocess.py:93} INFO - [0m14:55:45    role: None
[2024-05-01T17:55:45.104+0300] {subprocess.py:93} INFO - [0m14:55:45    search_path: None
[2024-05-01T17:55:45.106+0300] {subprocess.py:93} INFO - [0m14:55:45    keepalives_idle: 0
[2024-05-01T17:55:45.107+0300] {subprocess.py:93} INFO - [0m14:55:45    sslmode: None
[2024-05-01T17:55:45.109+0300] {subprocess.py:93} INFO - [0m14:55:45    sslcert: None
[2024-05-01T17:55:45.110+0300] {subprocess.py:93} INFO - [0m14:55:45    sslkey: None
[2024-05-01T17:55:45.110+0300] {subprocess.py:93} INFO - [0m14:55:45    sslrootcert: None
[2024-05-01T17:55:45.111+0300] {subprocess.py:93} INFO - [0m14:55:45    application_name: dbt
[2024-05-01T17:55:45.112+0300] {subprocess.py:93} INFO - [0m14:55:45    retries: 1
[2024-05-01T17:55:45.113+0300] {subprocess.py:93} INFO - [0m14:55:45  Registered adapter: postgres=1.7.13
[2024-05-01T17:55:45.153+0300] {subprocess.py:93} INFO - [0m14:55:45    Connection test: [[32mOK connection ok[0m]
[2024-05-01T17:55:45.154+0300] {subprocess.py:93} INFO - 
[2024-05-01T17:55:45.155+0300] {subprocess.py:93} INFO - [0m14:55:45  [31m1 check failed:[0m
[2024-05-01T17:55:45.158+0300] {subprocess.py:93} INFO - [0m14:55:45  Project loading failed for the following reason:
[2024-05-01T17:55:45.159+0300] {subprocess.py:93} INFO -  project path </tmp/airflowtmpxofrkscg/dbt_project.yml> not found
[2024-05-01T17:55:45.160+0300] {subprocess.py:93} INFO - 
[2024-05-01T17:55:46.738+0300] {subprocess.py:97} INFO - Command exited with return code 1
[2024-05-01T17:55:46.740+0300] {taskinstance.py:441} INFO - ::group::Post task execution logs
[2024-05-01T17:55:46.777+0300] {taskinstance.py:2890} ERROR - Task failed with exception
Traceback (most recent call last):
  File "/home/yohanes/Documents/10academy/week2_2/10ac_city_traffic_data_warehouse_week2/week2_env/lib/python3.8/site-packages/airflow/models/taskinstance.py", line 465, in _execute_task
    result = _execute_callable(context=context, **execute_callable_kwargs)
  File "/home/yohanes/Documents/10academy/week2_2/10ac_city_traffic_data_warehouse_week2/week2_env/lib/python3.8/site-packages/airflow/models/taskinstance.py", line 432, in _execute_callable
    return execute_callable(context=context, **execute_callable_kwargs)
  File "/home/yohanes/Documents/10academy/week2_2/10ac_city_traffic_data_warehouse_week2/week2_env/lib/python3.8/site-packages/airflow/models/baseoperator.py", line 400, in wrapper
    return func(self, *args, **kwargs)
  File "/home/yohanes/Documents/10academy/week2_2/10ac_city_traffic_data_warehouse_week2/week2_env/lib/python3.8/site-packages/airflow/operators/bash.py", line 243, in execute
    raise AirflowException(
airflow.exceptions.AirflowException: Bash command failed. The command returned a non-zero exit code 1.
[2024-05-01T17:55:46.784+0300] {taskinstance.py:1205} INFO - Marking task as UP_FOR_RETRY. dag_id=dbt_dag, task_id=dbt_debug, execution_date=20240501T144452, start_date=20240501T145539, end_date=20240501T145546
[2024-05-01T17:55:46.860+0300] {standard_task_runner.py:110} ERROR - Failed to execute job 61 for task dbt_debug (Bash command failed. The command returned a non-zero exit code 1.; 26148)
[2024-05-01T17:55:46.886+0300] {local_task_job_runner.py:240} INFO - Task exited with return code 1
[2024-05-01T17:55:46.940+0300] {taskinstance.py:3482} INFO - 0 downstream tasks scheduled from follow-on schedule check
[2024-05-01T17:55:46.948+0300] {local_task_job_runner.py:222} INFO - ::endgroup::
