[2024-05-01T17:50:29.096+0300] {local_task_job_runner.py:120} INFO - ::group::Pre task execution logs
[2024-05-01T17:50:29.147+0300] {taskinstance.py:2073} INFO - Dependencies all met for dep_context=non-requeueable deps ti=<TaskInstance: dbt_dag.dbt_debug manual__2024-05-01T14:44:52.332667+00:00 [queued]>
[2024-05-01T17:50:29.162+0300] {taskinstance.py:2073} INFO - Dependencies all met for dep_context=requeueable deps ti=<TaskInstance: dbt_dag.dbt_debug manual__2024-05-01T14:44:52.332667+00:00 [queued]>
[2024-05-01T17:50:29.162+0300] {taskinstance.py:2303} INFO - Starting attempt 2 of 4
[2024-05-01T17:50:29.365+0300] {taskinstance.py:2327} INFO - Executing <Task(BashOperator): dbt_debug> on 2024-05-01 14:44:52.332667+00:00
[2024-05-01T17:50:29.371+0300] {standard_task_runner.py:63} INFO - Started process 20914 to run task
[2024-05-01T17:50:29.377+0300] {standard_task_runner.py:90} INFO - Running: ['airflow', 'tasks', 'run', 'dbt_dag', 'dbt_debug', 'manual__2024-05-01T14:44:52.332667+00:00', '--job-id', '59', '--raw', '--subdir', 'DAGS_FOLDER/bash.py', '--cfg-path', '/tmp/tmp6r9wpmkg']
[2024-05-01T17:50:29.379+0300] {standard_task_runner.py:91} INFO - Job 59: Subtask dbt_debug
[2024-05-01T17:50:29.526+0300] {task_command.py:426} INFO - Running <TaskInstance: dbt_dag.dbt_debug manual__2024-05-01T14:44:52.332667+00:00 [running]> on host yohanes-Satellite-Pro-C50-A363
[2024-05-01T17:50:29.763+0300] {taskinstance.py:2644} INFO - Exporting env vars: AIRFLOW_CTX_DAG_OWNER='airflow' AIRFLOW_CTX_DAG_ID='dbt_dag' AIRFLOW_CTX_TASK_ID='dbt_debug' AIRFLOW_CTX_EXECUTION_DATE='2024-05-01T14:44:52.332667+00:00' AIRFLOW_CTX_TRY_NUMBER='2' AIRFLOW_CTX_DAG_RUN_ID='manual__2024-05-01T14:44:52.332667+00:00'
[2024-05-01T17:50:29.764+0300] {taskinstance.py:430} INFO - ::endgroup::
[2024-05-01T17:50:29.791+0300] {subprocess.py:63} INFO - Tmp dir root location: /tmp
[2024-05-01T17:50:29.792+0300] {subprocess.py:75} INFO - Running command: ['/usr/bin/bash', '-c', 'dbt debug']
[2024-05-01T17:50:29.804+0300] {subprocess.py:86} INFO - Output:
[2024-05-01T17:50:34.196+0300] {subprocess.py:93} INFO - [0m14:50:34  Running with dbt=1.7.13
[2024-05-01T17:50:34.199+0300] {subprocess.py:93} INFO - [0m14:50:34  dbt version: 1.7.13
[2024-05-01T17:50:34.200+0300] {subprocess.py:93} INFO - [0m14:50:34  python version: 3.8.10
[2024-05-01T17:50:34.200+0300] {subprocess.py:93} INFO - [0m14:50:34  python path: /home/yohanes/Documents/10academy/week2_2/10ac_city_traffic_data_warehouse_week2/week2_env/bin/python3
[2024-05-01T17:50:34.201+0300] {subprocess.py:93} INFO - [0m14:50:34  os info: Linux-5.15.0-105-generic-x86_64-with-glibc2.29
[2024-05-01T17:50:34.381+0300] {subprocess.py:93} INFO - [0m14:50:34  Using profiles dir at /home/yohanes/.dbt
[2024-05-01T17:50:34.382+0300] {subprocess.py:93} INFO - [0m14:50:34  Using profiles.yml file at /home/yohanes/.dbt/profiles.yml
[2024-05-01T17:50:34.383+0300] {subprocess.py:93} INFO - [0m14:50:34  Using dbt_project.yml file at /tmp/airflowtmpdid37wpq/dbt_project.yml
[2024-05-01T17:50:34.385+0300] {subprocess.py:93} INFO - [0m14:50:34  adapter type: postgres
[2024-05-01T17:50:34.386+0300] {subprocess.py:93} INFO - [0m14:50:34  adapter version: 1.7.13
[2024-05-01T17:50:34.387+0300] {subprocess.py:93} INFO - [0m14:50:34  Configuration:
[2024-05-01T17:50:34.388+0300] {subprocess.py:93} INFO - [0m14:50:34    profiles.yml file [[32mOK found and valid[0m]
[2024-05-01T17:50:34.389+0300] {subprocess.py:93} INFO - [0m14:50:34    dbt_project.yml file [[31mERROR not found[0m]
[2024-05-01T17:50:34.391+0300] {subprocess.py:93} INFO - [0m14:50:34  Required dependencies:
[2024-05-01T17:50:34.409+0300] {subprocess.py:93} INFO - [0m14:50:34   - git [[32mOK found[0m]
[2024-05-01T17:50:34.410+0300] {subprocess.py:93} INFO - 
[2024-05-01T17:50:34.411+0300] {subprocess.py:93} INFO - [0m14:50:34  Connection:
[2024-05-01T17:50:34.412+0300] {subprocess.py:93} INFO - [0m14:50:34    host: localhost
[2024-05-01T17:50:34.413+0300] {subprocess.py:93} INFO - [0m14:50:34    port: 5432
[2024-05-01T17:50:34.415+0300] {subprocess.py:93} INFO - [0m14:50:34    user: postgres
[2024-05-01T17:50:34.417+0300] {subprocess.py:93} INFO - [0m14:50:34    database: traffic
[2024-05-01T17:50:34.418+0300] {subprocess.py:93} INFO - [0m14:50:34    schema: traffic_schema
[2024-05-01T17:50:34.420+0300] {subprocess.py:93} INFO - [0m14:50:34    connect_timeout: 10
[2024-05-01T17:50:34.422+0300] {subprocess.py:93} INFO - [0m14:50:34    role: None
[2024-05-01T17:50:34.424+0300] {subprocess.py:93} INFO - [0m14:50:34    search_path: None
[2024-05-01T17:50:34.425+0300] {subprocess.py:93} INFO - [0m14:50:34    keepalives_idle: 0
[2024-05-01T17:50:34.427+0300] {subprocess.py:93} INFO - [0m14:50:34    sslmode: None
[2024-05-01T17:50:34.428+0300] {subprocess.py:93} INFO - [0m14:50:34    sslcert: None
[2024-05-01T17:50:34.429+0300] {subprocess.py:93} INFO - [0m14:50:34    sslkey: None
[2024-05-01T17:50:34.431+0300] {subprocess.py:93} INFO - [0m14:50:34    sslrootcert: None
[2024-05-01T17:50:34.433+0300] {subprocess.py:93} INFO - [0m14:50:34    application_name: dbt
[2024-05-01T17:50:34.434+0300] {subprocess.py:93} INFO - [0m14:50:34    retries: 1
[2024-05-01T17:50:34.436+0300] {subprocess.py:93} INFO - [0m14:50:34  Registered adapter: postgres=1.7.13
[2024-05-01T17:50:34.476+0300] {subprocess.py:93} INFO - [0m14:50:34    Connection test: [[32mOK connection ok[0m]
[2024-05-01T17:50:34.477+0300] {subprocess.py:93} INFO - 
[2024-05-01T17:50:34.483+0300] {subprocess.py:93} INFO - [0m14:50:34  [31m1 check failed:[0m
[2024-05-01T17:50:34.487+0300] {subprocess.py:93} INFO - [0m14:50:34  Project loading failed for the following reason:
[2024-05-01T17:50:34.488+0300] {subprocess.py:93} INFO -  project path </tmp/airflowtmpdid37wpq/dbt_project.yml> not found
[2024-05-01T17:50:34.488+0300] {subprocess.py:93} INFO - 
[2024-05-01T17:50:36.042+0300] {subprocess.py:97} INFO - Command exited with return code 1
[2024-05-01T17:50:36.044+0300] {taskinstance.py:441} INFO - ::group::Post task execution logs
[2024-05-01T17:50:36.080+0300] {taskinstance.py:2890} ERROR - Task failed with exception
Traceback (most recent call last):
  File "/home/yohanes/Documents/10academy/week2_2/10ac_city_traffic_data_warehouse_week2/week2_env/lib/python3.8/site-packages/airflow/models/taskinstance.py", line 465, in _execute_task
    result = _execute_callable(context=context, **execute_callable_kwargs)
  File "/home/yohanes/Documents/10academy/week2_2/10ac_city_traffic_data_warehouse_week2/week2_env/lib/python3.8/site-packages/airflow/models/taskinstance.py", line 432, in _execute_callable
    return execute_callable(context=context, **execute_callable_kwargs)
  File "/home/yohanes/Documents/10academy/week2_2/10ac_city_traffic_data_warehouse_week2/week2_env/lib/python3.8/site-packages/airflow/models/baseoperator.py", line 400, in wrapper
    return func(self, *args, **kwargs)
  File "/home/yohanes/Documents/10academy/week2_2/10ac_city_traffic_data_warehouse_week2/week2_env/lib/python3.8/site-packages/airflow/operators/bash.py", line 243, in execute
    raise AirflowException(
airflow.exceptions.AirflowException: Bash command failed. The command returned a non-zero exit code 1.
[2024-05-01T17:50:36.088+0300] {taskinstance.py:1205} INFO - Marking task as UP_FOR_RETRY. dag_id=dbt_dag, task_id=dbt_debug, execution_date=20240501T144452, start_date=20240501T145029, end_date=20240501T145036
[2024-05-01T17:50:36.255+0300] {standard_task_runner.py:110} ERROR - Failed to execute job 59 for task dbt_debug (Bash command failed. The command returned a non-zero exit code 1.; 20914)
[2024-05-01T17:50:36.280+0300] {local_task_job_runner.py:240} INFO - Task exited with return code 1
[2024-05-01T17:50:36.333+0300] {taskinstance.py:3482} INFO - 0 downstream tasks scheduled from follow-on schedule check
[2024-05-01T17:50:36.344+0300] {local_task_job_runner.py:222} INFO - ::endgroup::
